import logging
import sys

from celery import shared_task
from celery.exceptions import Ignore, Reject
from dateutil import parser
from django.core.cache import cache
from django.conf import settings
from django.contrib.auth.models import User
from fitapp.models import UserFitbit
from tracktivityPetsWebsite.utils import update_user_fitbit, update_user_challenges

logger = logging.getLogger(__name__)
logger.setLevel(logging.DEBUG)
hdlr = logging.FileHandler('./tracktivitypets_tasks.log')
formatter = logging.Formatter('%(asctime)s %(levelname)s %(message)s')
hdlr.setFormatter(formatter)
logger.addHandler(hdlr)
logger.setLevel(logging.DEBUG)

LOCK_EXPIRE = 60 * 5 # Lock expires in 5 minutes

@shared_task
def update_user_with_fitbit(fitbit_user):
    """ Get the user's time series data """
    '''
    The update_user_with_fitbit task fetched a users time series fitbit data asynchronously
    The function then calls another function in utils.py to update the users active challenges
    '''
    logger.debug("Updating TracktivityPets local db for fitbit user: %s" % (fitbit_user))

    try:

        # Create a lock so we don't try to run the same task multiple times
        '''
        lock_id = '{0}-lock-{1}'.format(__name__, fitbit_user)
        if not cache.add(lock_id, 'true', LOCK_EXPIRE):
            logger.debug('Already updating fitbit name: %s' % (fitbit_user))
            raise Ignore()
        '''

        fbusers = UserFitbit.objects.filter(fitbit_user=fitbit_user)

        for fbuser in fbusers:
            logger.debug("About to update TracktivityPets local db for TPets user: %s" % (fbuser.user.get_username()))
            update_user_fitbit(fbuser.user)
            check_user_challenges.delay(fbuser.user)
        #release lock
        #cache.delete(lock_id)
    except Exception as e:
        logger.exception(e)

@shared_task
def check_user_challenges(user):
    logger.debug("check user challenges task started for user: %s" % user.get_username())

    try:
        update_user_challenges(user)
    except Exception as e:
        logger.exception("Error occured during user challenge check. User: %s", user.get_username())
    logger.debug("check user challenges task finished for user: %s" % user.get_username())
